<robot name = "robot">
    <link name="Body0">
        <inertial>
            <origin xyz="0 0 2.348528445752517" rpy="0 0 0"/>
            <mass value="1" />
            <inertia ixx="100" ixy="0" ixz="0" iyy="100" iyz="0" izz="100" />
        </inertial>
        <visual>
            <origin xyz="0 0 2.348528445752517" rpy="0 0 0"/>
            <geometry>
                <box size="0.11340963925611836 0.83093449190615 0.6970568915050342" />
            </geometry>
            <material name="Blue">
                <color rgba="0 0 1.0 1.0"/>
            </material>
        </visual>
        <collision>
            <origin xyz="0 0 2.348528445752517" rpy="0 0 0"/>
            <geometry>
                <box size="0.11340963925611836 0.83093449190615 0.6970568915050342" />
            </geometry>
        </collision>
    </link>
    <joint name="Body0_Body1" type="revolute">
       <parent link="Body0"/>
       <child  link="Body1"/>
       <origin rpy="0 0 0" xyz="0.05670481962805918 0 2.348528445752517" />
     <axis xyz="0 1 0"/>
       <limit effort="0.0" lower="-3.14159" upper="3.14159" velocity="0.0"/>
    </joint>
    <link name="Body1">
        <inertial>
            <origin xyz="0.48745016063884855 0 0" rpy="0 0 0"/>
            <mass value="1" />
            <inertia ixx="100" ixy="0" ixz="0" iyy="100" iyz="0" izz="100" />
        </inertial>
        <visual>
            <origin xyz="0.48745016063884855 0 0" rpy="0 0 0"/>
            <geometry>
                <box size="0.9749003212776971 0.43028252312353577 0.5721506278104266" />
            </geometry>
            <material name="Green">
                <color rgba="0 1.0 0 1.0"/>
            </material>
        </visual>
        <collision>
            <origin xyz="0.48745016063884855 0 0" rpy="0 0 0"/>
            <geometry>
                <box size="0.9749003212776971 0.43028252312353577 0.5721506278104266" />
            </geometry>
        </collision>
    </link>
    <joint name="Body1_Body2" type="revolute">
       <parent link="Body1"/>
       <child  link="Body2"/>
       <origin rpy="0 0 0" xyz="0.9749003212776971 0 0" />
     <axis xyz="0 0 1"/>
       <limit effort="0.0" lower="-3.14159" upper="3.14159" velocity="0.0"/>
    </joint>
    <joint name="Body1_Body3" type="revolute">
       <parent link="Body1"/>
       <child  link="Body3"/>
       <origin rpy="0 0 0" xyz="0.48745016063884855 0.21514126156176788 0" />
     <axis xyz="0 0 1"/>
       <limit effort="0.0" lower="-3.14159" upper="3.14159" velocity="0.0"/>
    </joint>
    <link name="Body3">
        <inertial>
            <origin xyz="0 0.038581383297416706 0" rpy="0 0 0"/>
            <mass value="1" />
            <inertia ixx="100" ixy="0" ixz="0" iyy="100" iyz="0" izz="100" />
        </inertial>
        <visual>
            <origin xyz="0 0.038581383297416706 0" rpy="0 0 0"/>
            <geometry>
                <box size="0.8402378187983789 0.07716276659483341 0.13318581750175926" />
            </geometry>
            <material name="Blue">
                <color rgba="0 0 1.0 1.0"/>
            </material>
        </visual>
        <collision>
            <origin xyz="0 0.038581383297416706 0" rpy="0 0 0"/>
            <geometry>
                <box size="0.8402378187983789 0.07716276659483341 0.13318581750175926" />
            </geometry>
        </collision>
    </link>
    <joint name="Body3_Body4" type="revolute">
       <parent link="Body3"/>
       <child  link="Body4"/>
       <origin rpy="0 0 0" xyz="0 0.07716276659483341 -0.06659290875087963" />
     <axis xyz="0 0 1"/>
       <limit effort="0.0" lower="-3.14159" upper="3.14159" velocity="0.0"/>
    </joint>
    <link name="Body4">
        <inertial>
            <origin xyz="0 0 -0.5" rpy="0 0 0"/>
            <mass value="1" />
            <inertia ixx="100" ixy="0" ixz="0" iyy="100" iyz="0" izz="100" />
        </inertial>
        <visual>
            <origin xyz="0 0 -0.5" rpy="0 0 0"/>
            <geometry>
                <box size="0.48301627444291495 1 1" />
            </geometry>
            <material name="Green">
                <color rgba="0 1.0 0 1.0"/>
            </material>
        </visual>
        <collision>
            <origin xyz="0 0 -0.5" rpy="0 0 0"/>
            <geometry>
                <box size="0.48301627444291495 1 1" />
            </geometry>
        </collision>
    </link>
    <link name="Body2">
        <inertial>
            <origin xyz="0.061662887082780546 0 0" rpy="0 0 0"/>
            <mass value="1" />
            <inertia ixx="100" ixy="0" ixz="0" iyy="100" iyz="0" izz="100" />
        </inertial>
        <visual>
            <origin xyz="0.061662887082780546 0 0" rpy="0 0 0"/>
            <geometry>
                <box size="0.12332577416556109 0.838828389637362 0.6251764667596383" />
            </geometry>
            <material name="Blue">
                <color rgba="0 0 1.0 1.0"/>
            </material>
        </visual>
        <collision>
            <origin xyz="0.061662887082780546 0 0" rpy="0 0 0"/>
            <geometry>
                <box size="0.12332577416556109 0.838828389637362 0.6251764667596383" />
            </geometry>
        </collision>
    </link>
    <joint name="Body2_Body5" type="revolute">
       <parent link="Body2"/>
       <child  link="Body5"/>
       <origin rpy="0 0 0" xyz="0.061662887082780546 0.419414194818681 0" />
     <axis xyz="0 1 0"/>
       <limit effort="0.0" lower="-3.14159" upper="3.14159" velocity="0.0"/>
    </joint>
    <link name="Body5">
        <inertial>
            <origin xyz="0 0.09236805391368393 0" rpy="0 0 0"/>
            <mass value="1" />
            <inertia ixx="100" ixy="0" ixz="0" iyy="100" iyz="0" izz="100" />
        </inertial>
        <visual>
            <origin xyz="0 0.09236805391368393 0" rpy="0 0 0"/>
            <geometry>
                <box size="0.05172264586242172 0.18473610782736785 0.5585847054177573" />
            </geometry>
            <material name="Green">
                <color rgba="0 1.0 0 1.0"/>
            </material>
        </visual>
        <collision>
            <origin xyz="0 0.09236805391368393 0" rpy="0 0 0"/>
            <geometry>
                <box size="0.05172264586242172 0.18473610782736785 0.5585847054177573" />
            </geometry>
        </collision>
    </link>
    <joint name="Body5_Body6" type="revolute">
       <parent link="Body5"/>
       <child  link="Body6"/>
       <origin rpy="0 0 0" xyz="0 0.18473610782736785 -0.27929235270887864" />
     <axis xyz="0 0 1"/>
       <limit effort="0.0" lower="-3.14159" upper="3.14159" velocity="0.0"/>
    </joint>
    <link name="Body6">
        <inertial>
            <origin xyz="0 0 -0.5" rpy="0 0 0"/>
            <mass value="1" />
            <inertia ixx="100" ixy="0" ixz="0" iyy="100" iyz="0" izz="100" />
        </inertial>
        <visual>
            <origin xyz="0 0 -0.5" rpy="0 0 0"/>
            <geometry>
                <box size="0.075576194067038 1 1" />
            </geometry>
            <material name="Blue">
                <color rgba="0 0 1.0 1.0"/>
            </material>
        </visual>
        <collision>
            <origin xyz="0 0 -0.5" rpy="0 0 0"/>
            <geometry>
                <box size="0.075576194067038 1 1" />
            </geometry>
        </collision>
    </link>
    <joint name="Body2_Body7" type="revolute">
       <parent link="Body2"/>
       <child  link="Body7"/>
       <origin rpy="0 0 0" xyz="0.061662887082780546 -0.419414194818681 0" />
     <axis xyz="0 0 1"/>
       <limit effort="0.0" lower="-3.14159" upper="3.14159" velocity="0.0"/>
    </joint>
    <link name="Body7">
        <inertial>
            <origin xyz="0 -0.5 0" rpy="0 0 0"/>
            <mass value="1" />
            <inertia ixx="100" ixy="0" ixz="0" iyy="100" iyz="0" izz="100" />
        </inertial>
        <visual>
            <origin xyz="0 -0.5 0" rpy="0 0 0"/>
            <geometry>
                <box size="0.08134761896983914 1 1" />
            </geometry>
            <material name="Blue">
                <color rgba="0 0 1.0 1.0"/>
            </material>
        </visual>
        <collision>
            <origin xyz="0 -0.5 0" rpy="0 0 0"/>
            <geometry>
                <box size="0.08134761896983914 1 1" />
            </geometry>
        </collision>
    </link>
</robot>