<robot name = "robot">
    <link name="Body0">
        <inertial>
            <origin xyz="0 0 2.358106494077519" rpy="0 0 0"/>
            <mass value="1" />
            <inertia ixx="100" ixy="0" ixz="0" iyy="100" iyz="0" izz="100" />
        </inertial>
        <visual>
            <origin xyz="0 0 2.358106494077519" rpy="0 0 0"/>
            <geometry>
                <box size="0.3750470351867533 0.9719076236832661 0.7162129881550383" />
            </geometry>
            <material name="Blue">
                <color rgba="0 0 1.0 1.0"/>
            </material>
        </visual>
        <collision>
            <origin xyz="0 0 2.358106494077519" rpy="0 0 0"/>
            <geometry>
                <box size="0.3750470351867533 0.9719076236832661 0.7162129881550383" />
            </geometry>
        </collision>
    </link>
    <joint name="Body0_Body1" type="revolute">
       <parent link="Body0"/>
       <child  link="Body1"/>
       <origin rpy="0 0 0" xyz="0.18752351759337665 0 2.358106494077519" />
     <axis xyz="0 0 1"/>
       <limit effort="0.0" lower="-3.14159" upper="3.14159" velocity="0.0"/>
    </joint>
    <link name="Body1">
        <inertial>
            <origin xyz="0.46300144427512097 0 0" rpy="0 0 0"/>
            <mass value="1" />
            <inertia ixx="100" ixy="0" ixz="0" iyy="100" iyz="0" izz="100" />
        </inertial>
        <visual>
            <origin xyz="0.46300144427512097 0 0" rpy="0 0 0"/>
            <geometry>
                <box size="0.9260028885502419 0.8108251223398693 0.5170944615239493" />
            </geometry>
            <material name="Green">
                <color rgba="0 1.0 0 1.0"/>
            </material>
        </visual>
        <collision>
            <origin xyz="0.46300144427512097 0 0" rpy="0 0 0"/>
            <geometry>
                <box size="0.9260028885502419 0.8108251223398693 0.5170944615239493" />
            </geometry>
        </collision>
    </link>
    <joint name="Body1_Body2" type="revolute">
       <parent link="Body1"/>
       <child  link="Body2"/>
       <origin rpy="0 0 0" xyz="0.46300144427512097 0.4054125611699346 0" />
     <axis xyz="1 0 0"/>
       <limit effort="0.0" lower="-3.14159" upper="3.14159" velocity="0.0"/>
    </joint>
    <link name="Body2">
        <inertial>
            <origin xyz="0 0.08989723755088147 0" rpy="0 0 0"/>
            <mass value="1" />
            <inertia ixx="100" ixy="0" ixz="0" iyy="100" iyz="0" izz="100" />
        </inertial>
        <visual>
            <origin xyz="0 0.08989723755088147 0" rpy="0 0 0"/>
            <geometry>
                <box size="0.9192345108463461 0.17979447510176294 0.3578810374578487" />
            </geometry>
            <material name="Blue">
                <color rgba="0 0 1.0 1.0"/>
            </material>
        </visual>
        <collision>
            <origin xyz="0 0.08989723755088147 0" rpy="0 0 0"/>
            <geometry>
                <box size="0.9192345108463461 0.17979447510176294 0.3578810374578487" />
            </geometry>
        </collision>
    </link>
    <joint name="Body2_Body3" type="revolute">
       <parent link="Body2"/>
       <child  link="Body3"/>
       <origin rpy="0 0 0" xyz="0 0.17979447510176294 -0.17894051872892436" />
     <axis xyz="1 0 0"/>
       <limit effort="0.0" lower="-3.14159" upper="3.14159" velocity="0.0"/>
    </joint>
    <link name="Body3">
        <inertial>
            <origin xyz="0 0 -0.13084855185316085" rpy="0 0 0"/>
            <mass value="1" />
            <inertia ixx="100" ixy="0" ixz="0" iyy="100" iyz="0" izz="100" />
        </inertial>
        <visual>
            <origin xyz="0 0 -0.13084855185316085" rpy="0 0 0"/>
            <geometry>
                <box size="0.11757900205900915 0.04304870560957919 0.2616971037063217" />
            </geometry>
            <material name="Green">
                <color rgba="0 1.0 0 1.0"/>
            </material>
        </visual>
        <collision>
            <origin xyz="0 0 -0.13084855185316085" rpy="0 0 0"/>
            <geometry>
                <box size="0.11757900205900915 0.04304870560957919 0.2616971037063217" />
            </geometry>
        </collision>
    </link>
</robot>