<robot name = "robot">
    <link name="Body0">
        <inertial>
            <origin xyz="0 0 0.3065393916111194" rpy="0 0 0"/>
            <mass value="1" />
            <inertia ixx="100" ixy="0" ixz="0" iyy="100" iyz="0" izz="100" />
        </inertial>
        <visual>
            <origin xyz="0 0 0.3065393916111194" rpy="0 0 0"/>
            <geometry>
                <box size="0.5832816933457781 0.8995547033589129 0.6130787832222389" />
            </geometry>
            <material name="Green">
                <color rgba="0 1.0 0 1.0"/>
            </material>
        </visual>
        <collision>
            <origin xyz="0 0 0.3065393916111194" rpy="0 0 0"/>
            <geometry>
                <box size="0.5832816933457781 0.8995547033589129 0.6130787832222389" />
            </geometry>
        </collision>
    </link>
    <joint name="Body0_Body1" type="revolute">
       <parent link="Body0"/>
       <child  link="Body1"/>
       <origin rpy="0 0 0" xyz="0.29164084667288903 0 0.3065393916111194" />
     <axis xyz="0 1 0"/>
       <limit effort="0.0" lower="-3.14159" upper="3.14159" velocity="0.0"/>
    </joint>
    <link name="Body1">
        <inertial>
            <origin xyz="0.3531455627137092 0 0" rpy="0 0 0"/>
            <mass value="1" />
            <inertia ixx="100" ixy="0" ixz="0" iyy="100" iyz="0" izz="100" />
        </inertial>
        <visual>
            <origin xyz="0.3531455627137092 0 0" rpy="0 0 0"/>
            <geometry>
                <box size="0.7062911254274185 0.15666675362512125 0.8463862324895707" />
            </geometry>
            <material name="Green">
                <color rgba="0 1.0 0 1.0"/>
            </material>
        </visual>
        <collision>
            <origin xyz="0.3531455627137092 0 0" rpy="0 0 0"/>
            <geometry>
                <box size="0.7062911254274185 0.15666675362512125 0.8463862324895707" />
            </geometry>
        </collision>
    </link>
    <joint name="Body1_Body2" type="revolute">
       <parent link="Body1"/>
       <child  link="Body2"/>
       <origin rpy="0 0 0" xyz="0.7062911254274185 0 0" />
     <axis xyz="1 0 0"/>
       <limit effort="0.0" lower="-3.14159" upper="3.14159" velocity="0.0"/>
    </joint>
    <link name="Body2">
        <inertial>
            <origin xyz="0.28454637571456476 0 0" rpy="0 0 0"/>
            <mass value="1" />
            <inertia ixx="100" ixy="0" ixz="0" iyy="100" iyz="0" izz="100" />
        </inertial>
        <visual>
            <origin xyz="0.28454637571456476 0 0" rpy="0 0 0"/>
            <geometry>
                <box size="0.5690927514291295 0.6173009998365012 0.2103804890135338" />
            </geometry>
            <material name="Green">
                <color rgba="0 1.0 0 1.0"/>
            </material>
        </visual>
        <collision>
            <origin xyz="0.28454637571456476 0 0" rpy="0 0 0"/>
            <geometry>
                <box size="0.5690927514291295 0.6173009998365012 0.2103804890135338" />
            </geometry>
        </collision>
    </link>
    <joint name="Body2_Body3" type="revolute">
       <parent link="Body2"/>
       <child  link="Body3"/>
       <origin rpy="0 0 0" xyz="0.5690927514291295 0 0" />
     <axis xyz="0 0 1"/>
       <limit effort="0.0" lower="-3.14159" upper="3.14159" velocity="0.0"/>
    </joint>
    <link name="Body3">
        <inertial>
            <origin xyz="0.37296287533820693 0 0" rpy="0 0 0"/>
            <mass value="1" />
            <inertia ixx="100" ixy="0" ixz="0" iyy="100" iyz="0" izz="100" />
        </inertial>
        <visual>
            <origin xyz="0.37296287533820693 0 0" rpy="0 0 0"/>
            <geometry>
                <box size="0.7459257506764139 0.9984662842337185 0.1822441725810225" />
            </geometry>
            <material name="Blue">
                <color rgba="0 0 1.0 1.0"/>
            </material>
        </visual>
        <collision>
            <origin xyz="0.37296287533820693 0 0" rpy="0 0 0"/>
            <geometry>
                <box size="0.7459257506764139 0.9984662842337185 0.1822441725810225" />
            </geometry>
        </collision>
    </link>
    <joint name="Body3_Body4" type="revolute">
       <parent link="Body3"/>
       <child  link="Body4"/>
       <origin rpy="0 0 0" xyz="0.7459257506764139 0 0" />
     <axis xyz="0 1 0"/>
       <limit effort="0.0" lower="-3.14159" upper="3.14159" velocity="0.0"/>
    </joint>
    <link name="Body4">
        <inertial>
            <origin xyz="0.11463224621595919 0 0" rpy="0 0 0"/>
            <mass value="1" />
            <inertia ixx="100" ixy="0" ixz="0" iyy="100" iyz="0" izz="100" />
        </inertial>
        <visual>
            <origin xyz="0.11463224621595919 0 0" rpy="0 0 0"/>
            <geometry>
                <box size="0.22926449243191838 0.8563022050091909 0.9135715958523211" />
            </geometry>
            <material name="Blue">
                <color rgba="0 0 1.0 1.0"/>
            </material>
        </visual>
        <collision>
            <origin xyz="0.11463224621595919 0 0" rpy="0 0 0"/>
            <geometry>
                <box size="0.22926449243191838 0.8563022050091909 0.9135715958523211" />
            </geometry>
        </collision>
    </link>
    <joint name="Body4_Body5" type="revolute">
       <parent link="Body4"/>
       <child  link="Body5"/>
       <origin rpy="0 0 0" xyz="0.22926449243191838 0 0" />
     <axis xyz="1 0 0"/>
       <limit effort="0.0" lower="-3.14159" upper="3.14159" velocity="0.0"/>
    </joint>
    <link name="Body5">
        <inertial>
            <origin xyz="0.17708591577818683 0 0" rpy="0 0 0"/>
            <mass value="1" />
            <inertia ixx="100" ixy="0" ixz="0" iyy="100" iyz="0" izz="100" />
        </inertial>
        <visual>
            <origin xyz="0.17708591577818683 0 0" rpy="0 0 0"/>
            <geometry>
                <box size="0.35417183155637366 0.8124639635173087 0.8827781089674276" />
            </geometry>
            <material name="Green">
                <color rgba="0 1.0 0 1.0"/>
            </material>
        </visual>
        <collision>
            <origin xyz="0.17708591577818683 0 0" rpy="0 0 0"/>
            <geometry>
                <box size="0.35417183155637366 0.8124639635173087 0.8827781089674276" />
            </geometry>
        </collision>
    </link>
    <joint name="Body5_Body6" type="revolute">
       <parent link="Body5"/>
       <child  link="Body6"/>
       <origin rpy="0 0 0" xyz="0.35417183155637366 0 0" />
     <axis xyz="1 0 0"/>
       <limit effort="0.0" lower="-3.14159" upper="3.14159" velocity="0.0"/>
    </joint>
    <link name="Body6">
        <inertial>
            <origin xyz="0.2906395697330874 0 0" rpy="0 0 0"/>
            <mass value="1" />
            <inertia ixx="100" ixy="0" ixz="0" iyy="100" iyz="0" izz="100" />
        </inertial>
        <visual>
            <origin xyz="0.2906395697330874 0 0" rpy="0 0 0"/>
            <geometry>
                <box size="0.5812791394661748 0.842157341910121 0.553087177678866" />
            </geometry>
            <material name="Green">
                <color rgba="0 1.0 0 1.0"/>
            </material>
        </visual>
        <collision>
            <origin xyz="0.2906395697330874 0 0" rpy="0 0 0"/>
            <geometry>
                <box size="0.5812791394661748 0.842157341910121 0.553087177678866" />
            </geometry>
        </collision>
    </link>
    <joint name="Body6_Body7" type="revolute">
       <parent link="Body6"/>
       <child  link="Body7"/>
       <origin rpy="0 0 0" xyz="0.5812791394661748 0 0" />
     <axis xyz="1 0 0"/>
       <limit effort="0.0" lower="-3.14159" upper="3.14159" velocity="0.0"/>
    </joint>
    <link name="Body7">
        <inertial>
            <origin xyz="0.12925373270979226 0 0" rpy="0 0 0"/>
            <mass value="1" />
            <inertia ixx="100" ixy="0" ixz="0" iyy="100" iyz="0" izz="100" />
        </inertial>
        <visual>
            <origin xyz="0.12925373270979226 0 0" rpy="0 0 0"/>
            <geometry>
                <box size="0.2585074654195845 0.7731318326426369 0.4692621110669062" />
            </geometry>
            <material name="Green">
                <color rgba="0 1.0 0 1.0"/>
            </material>
        </visual>
        <collision>
            <origin xyz="0.12925373270979226 0 0" rpy="0 0 0"/>
            <geometry>
                <box size="0.2585074654195845 0.7731318326426369 0.4692621110669062" />
            </geometry>
        </collision>
    </link>
</robot>