<robot name = "robot">
    <link name="Body0">
        <inertial>
            <origin xyz="0 0 0.13307981313038292" rpy="0 0 0"/>
            <mass value="1" />
            <inertia ixx="100" ixy="0" ixz="0" iyy="100" iyz="0" izz="100" />
        </inertial>
        <visual>
            <origin xyz="0 0 0.13307981313038292" rpy="0 0 0"/>
            <geometry>
                <box size="0.6592669112032228 0.21608717719202974 0.26615962626076584" />
            </geometry>
            <material name="Green">
                <color rgba="0 1.0 0 1.0"/>
            </material>
        </visual>
        <collision>
            <origin xyz="0 0 0.13307981313038292" rpy="0 0 0"/>
            <geometry>
                <box size="0.6592669112032228 0.21608717719202974 0.26615962626076584" />
            </geometry>
        </collision>
    </link>
    <joint name="Body0_Body1" type="revolute">
       <parent link="Body0"/>
       <child  link="Body1"/>
       <origin rpy="0 0 0" xyz="0.3296334556016114 0 0.13307981313038292" />
     <axis xyz="0 0 1"/>
       <limit effort="0.0" lower="-3.14159" upper="3.14159" velocity="0.0"/>
    </joint>
    <link name="Body1">
        <inertial>
            <origin xyz="0.06124679234819854 0 0" rpy="0 0 0"/>
            <mass value="1" />
            <inertia ixx="100" ixy="0" ixz="0" iyy="100" iyz="0" izz="100" />
        </inertial>
        <visual>
            <origin xyz="0.06124679234819854 0 0" rpy="0 0 0"/>
            <geometry>
                <box size="0.12249358469639708 0.24777468462801588 0.23135833386792004" />
            </geometry>
            <material name="Green">
                <color rgba="0 1.0 0 1.0"/>
            </material>
        </visual>
        <collision>
            <origin xyz="0.06124679234819854 0 0" rpy="0 0 0"/>
            <geometry>
                <box size="0.12249358469639708 0.24777468462801588 0.23135833386792004" />
            </geometry>
        </collision>
    </link>
    <joint name="Body1_Body2" type="revolute">
       <parent link="Body1"/>
       <child  link="Body2"/>
       <origin rpy="0 0 0" xyz="0.12249358469639708 0 0" />
     <axis xyz="0 0 1"/>
       <limit effort="0.0" lower="-3.14159" upper="3.14159" velocity="0.0"/>
    </joint>
    <link name="Body2">
        <inertial>
            <origin xyz="0.4081625770607794 0 0" rpy="0 0 0"/>
            <mass value="1" />
            <inertia ixx="100" ixy="0" ixz="0" iyy="100" iyz="0" izz="100" />
        </inertial>
        <visual>
            <origin xyz="0.4081625770607794 0 0" rpy="0 0 0"/>
            <geometry>
                <box size="0.8163251541215588 0.20579050476251515 0.3276074166629248" />
            </geometry>
            <material name="Green">
                <color rgba="0 1.0 0 1.0"/>
            </material>
        </visual>
        <collision>
            <origin xyz="0.4081625770607794 0 0" rpy="0 0 0"/>
            <geometry>
                <box size="0.8163251541215588 0.20579050476251515 0.3276074166629248" />
            </geometry>
        </collision>
    </link>
    <joint name="Body2_Body3" type="revolute">
       <parent link="Body2"/>
       <child  link="Body3"/>
       <origin rpy="0 0 0" xyz="0.8163251541215588 0 0" />
     <axis xyz="0 0 1"/>
       <limit effort="0.0" lower="-3.14159" upper="3.14159" velocity="0.0"/>
    </joint>
    <link name="Body3">
        <inertial>
            <origin xyz="0.14673616533731604 0 0" rpy="0 0 0"/>
            <mass value="1" />
            <inertia ixx="100" ixy="0" ixz="0" iyy="100" iyz="0" izz="100" />
        </inertial>
        <visual>
            <origin xyz="0.14673616533731604 0 0" rpy="0 0 0"/>
            <geometry>
                <box size="0.2934723306746321 0.34607977259224443 0.46245585886543816" />
            </geometry>
            <material name="Green">
                <color rgba="0 1.0 0 1.0"/>
            </material>
        </visual>
        <collision>
            <origin xyz="0.14673616533731604 0 0" rpy="0 0 0"/>
            <geometry>
                <box size="0.2934723306746321 0.34607977259224443 0.46245585886543816" />
            </geometry>
        </collision>
    </link>
    <joint name="Body3_Body4" type="revolute">
       <parent link="Body3"/>
       <child  link="Body4"/>
       <origin rpy="0 0 0" xyz="0.2934723306746321 0 0" />
     <axis xyz="0 0 1"/>
       <limit effort="0.0" lower="-3.14159" upper="3.14159" velocity="0.0"/>
    </joint>
    <link name="Body4">
        <inertial>
            <origin xyz="0.47960747597987047 0 0" rpy="0 0 0"/>
            <mass value="1" />
            <inertia ixx="100" ixy="0" ixz="0" iyy="100" iyz="0" izz="100" />
        </inertial>
        <visual>
            <origin xyz="0.47960747597987047 0 0" rpy="0 0 0"/>
            <geometry>
                <box size="0.9592149519597409 0.3965186682816578 0.4987918234196761" />
            </geometry>
            <material name="Green">
                <color rgba="0 1.0 0 1.0"/>
            </material>
        </visual>
        <collision>
            <origin xyz="0.47960747597987047 0 0" rpy="0 0 0"/>
            <geometry>
                <box size="0.9592149519597409 0.3965186682816578 0.4987918234196761" />
            </geometry>
        </collision>
    </link>
    <joint name="Body4_Body5" type="revolute">
       <parent link="Body4"/>
       <child  link="Body5"/>
       <origin rpy="0 0 0" xyz="0.9592149519597409 0 0" />
     <axis xyz="0 0 1"/>
       <limit effort="0.0" lower="-3.14159" upper="3.14159" velocity="0.0"/>
    </joint>
    <link name="Body5">
        <inertial>
            <origin xyz="0.0559107167048149 0 0" rpy="0 0 0"/>
            <mass value="1" />
            <inertia ixx="100" ixy="0" ixz="0" iyy="100" iyz="0" izz="100" />
        </inertial>
        <visual>
            <origin xyz="0.0559107167048149 0 0" rpy="0 0 0"/>
            <geometry>
                <box size="0.1118214334096298 0.14331626757339677 0.488256148822093" />
            </geometry>
            <material name="Green">
                <color rgba="0 1.0 0 1.0"/>
            </material>
        </visual>
        <collision>
            <origin xyz="0.0559107167048149 0 0" rpy="0 0 0"/>
            <geometry>
                <box size="0.1118214334096298 0.14331626757339677 0.488256148822093" />
            </geometry>
        </collision>
    </link>
    <joint name="Body5_Body6" type="revolute">
       <parent link="Body5"/>
       <child  link="Body6"/>
       <origin rpy="0 0 0" xyz="0.1118214334096298 0 0" />
     <axis xyz="0 0 1"/>
       <limit effort="0.0" lower="-3.14159" upper="3.14159" velocity="0.0"/>
    </joint>
    <link name="Body6">
        <inertial>
            <origin xyz="0.24479459171739532 0 0" rpy="0 0 0"/>
            <mass value="1" />
            <inertia ixx="100" ixy="0" ixz="0" iyy="100" iyz="0" izz="100" />
        </inertial>
        <visual>
            <origin xyz="0.24479459171739532 0 0" rpy="0 0 0"/>
            <geometry>
                <box size="0.48958918343479063 0.15549514577817353 0.41429427627395043" />
            </geometry>
            <material name="Green">
                <color rgba="0 1.0 0 1.0"/>
            </material>
        </visual>
        <collision>
            <origin xyz="0.24479459171739532 0 0" rpy="0 0 0"/>
            <geometry>
                <box size="0.48958918343479063 0.15549514577817353 0.41429427627395043" />
            </geometry>
        </collision>
    </link>
    <joint name="Body6_Body7" type="revolute">
       <parent link="Body6"/>
       <child  link="Body7"/>
       <origin rpy="0 0 0" xyz="0.48958918343479063 0 0" />
     <axis xyz="0 0 1"/>
       <limit effort="0.0" lower="-3.14159" upper="3.14159" velocity="0.0"/>
    </joint>
    <link name="Body7">
        <inertial>
            <origin xyz="0.2657186373019766 0 0" rpy="0 0 0"/>
            <mass value="1" />
            <inertia ixx="100" ixy="0" ixz="0" iyy="100" iyz="0" izz="100" />
        </inertial>
        <visual>
            <origin xyz="0.2657186373019766 0 0" rpy="0 0 0"/>
            <geometry>
                <box size="0.5314372746039532 0.48811285905679547 0.31778483165295157" />
            </geometry>
            <material name="Blue">
                <color rgba="0 0 1.0 1.0"/>
            </material>
        </visual>
        <collision>
            <origin xyz="0.2657186373019766 0 0" rpy="0 0 0"/>
            <geometry>
                <box size="0.5314372746039532 0.48811285905679547 0.31778483165295157" />
            </geometry>
        </collision>
    </link>
    <joint name="Body7_Body8" type="revolute">
       <parent link="Body7"/>
       <child  link="Body8"/>
       <origin rpy="0 0 0" xyz="0.5314372746039532 0 0" />
     <axis xyz="0 0 1"/>
       <limit effort="0.0" lower="-3.14159" upper="3.14159" velocity="0.0"/>
    </joint>
    <link name="Body8">
        <inertial>
            <origin xyz="0.3902595879758195 0 0" rpy="0 0 0"/>
            <mass value="1" />
            <inertia ixx="100" ixy="0" ixz="0" iyy="100" iyz="0" izz="100" />
        </inertial>
        <visual>
            <origin xyz="0.3902595879758195 0 0" rpy="0 0 0"/>
            <geometry>
                <box size="0.780519175951639 0.2007053861599733 0.15771221895064308" />
            </geometry>
            <material name="Green">
                <color rgba="0 1.0 0 1.0"/>
            </material>
        </visual>
        <collision>
            <origin xyz="0.3902595879758195 0 0" rpy="0 0 0"/>
            <geometry>
                <box size="0.780519175951639 0.2007053861599733 0.15771221895064308" />
            </geometry>
        </collision>
    </link>
    <joint name="Body8_Body9" type="revolute">
       <parent link="Body8"/>
       <child  link="Body9"/>
       <origin rpy="0 0 0" xyz="0.780519175951639 0 0" />
     <axis xyz="0 0 1"/>
       <limit effort="0.0" lower="-3.14159" upper="3.14159" velocity="0.0"/>
    </joint>
    <link name="Body9">
        <inertial>
            <origin xyz="0.3227565030871846 0 0" rpy="0 0 0"/>
            <mass value="1" />
            <inertia ixx="100" ixy="0" ixz="0" iyy="100" iyz="0" izz="100" />
        </inertial>
        <visual>
            <origin xyz="0.3227565030871846 0 0" rpy="0 0 0"/>
            <geometry>
                <box size="0.6455130061743692 0.3144480504963476 0.4332510507750774" />
            </geometry>
            <material name="Green">
                <color rgba="0 1.0 0 1.0"/>
            </material>
        </visual>
        <collision>
            <origin xyz="0.3227565030871846 0 0" rpy="0 0 0"/>
            <geometry>
                <box size="0.6455130061743692 0.3144480504963476 0.4332510507750774" />
            </geometry>
        </collision>
    </link>
    <joint name="Body9_Body10" type="revolute">
       <parent link="Body9"/>
       <child  link="Body10"/>
       <origin rpy="0 0 0" xyz="0.6455130061743692 0 0" />
     <axis xyz="0 0 1"/>
       <limit effort="0.0" lower="-3.14159" upper="3.14159" velocity="0.0"/>
    </joint>
    <link name="Body10">
        <inertial>
            <origin xyz="0.3261320527771078 0 0" rpy="0 0 0"/>
            <mass value="1" />
            <inertia ixx="100" ixy="0" ixz="0" iyy="100" iyz="0" izz="100" />
        </inertial>
        <visual>
            <origin xyz="0.3261320527771078 0 0" rpy="0 0 0"/>
            <geometry>
                <box size="0.6522641055542155 0.40775309044276176 0.26163350620117043" />
            </geometry>
            <material name="Green">
                <color rgba="0 1.0 0 1.0"/>
            </material>
        </visual>
        <collision>
            <origin xyz="0.3261320527771078 0 0" rpy="0 0 0"/>
            <geometry>
                <box size="0.6522641055542155 0.40775309044276176 0.26163350620117043" />
            </geometry>
        </collision>
    </link>
</robot>