<robot name = "robot">
    <link name="Body0">
        <inertial>
            <origin xyz="0 0 0.08079607592879501" rpy="0 0 0"/>
            <mass value="1" />
            <inertia ixx="100" ixy="0" ixz="0" iyy="100" iyz="0" izz="100" />
        </inertial>
        <visual>
            <origin xyz="0 0 0.08079607592879501" rpy="0 0 0"/>
            <geometry>
                <box size="0.6129474314155764 0.3187289057395491 0.16159215185759002" />
            </geometry>
            <material name="Blue">
                <color rgba="0 0 1.0 1.0"/>
            </material>
        </visual>
        <collision>
            <origin xyz="0 0 0.08079607592879501" rpy="0 0 0"/>
            <geometry>
                <box size="0.6129474314155764 0.3187289057395491 0.16159215185759002" />
            </geometry>
        </collision>
    </link>
    <joint name="Body0_Body1" type="revolute">
       <parent link="Body0"/>
       <child  link="Body1"/>
       <origin rpy="0 0 0" xyz="0.3064737157077882 0 0.08079607592879501" />
     <axis xyz="0 0 1"/>
       <limit effort="0.0" lower="-3.14159" upper="3.14159" velocity="0.0"/>
    </joint>
    <link name="Body1">
        <inertial>
            <origin xyz="0.19620272419472495 0 0" rpy="0 0 0"/>
            <mass value="1" />
            <inertia ixx="100" ixy="0" ixz="0" iyy="100" iyz="0" izz="100" />
        </inertial>
        <visual>
            <origin xyz="0.19620272419472495 0 0" rpy="0 0 0"/>
            <geometry>
                <box size="0.3924054483894499 0.21962645178269136 0.34557431748193645" />
            </geometry>
            <material name="Green">
                <color rgba="0 1.0 0 1.0"/>
            </material>
        </visual>
        <collision>
            <origin xyz="0.19620272419472495 0 0" rpy="0 0 0"/>
            <geometry>
                <box size="0.3924054483894499 0.21962645178269136 0.34557431748193645" />
            </geometry>
        </collision>
    </link>
</robot>